<?xml version="1.0"?>
<robot name="quadruped_robot">

  <!-- Base Link -->
  <link name="base_link">
    <visual>
      <geometry>
        <box size="0.4 0.2 0.1"/>
      </geometry>
      <origin xyz="0 0 0.3" rpy="0 0 0" />
      <material name="blue">
        <color rgba="0 0 1 1" />
      </material>
    </visual>
  </link>

  <!-- Legs -->
  <!-- Repeat this section for each leg: front_left, front_right, rear_left, rear_right -->

  <!-- front_left -->
  <link name="leg_front_left_1">
    <visual>
      <geometry>
        <cylinder length="0.04" radius="0.01"/>
      </geometry>
      <origin xyz="0 0.02 0" rpy="1.5705 0 0" />
    </visual>
    <visual>
      <geometry>
        <sphere radius="0.02" />
      </geometry>
      <origin xyz="0 0 0" rpy="0 0 0" />
    </visual>
  </link>

  <joint name="joint_front_left_1" type="revolute">
    <parent link="base_link"/>
    <child link="leg_front_left_1"/>
    <origin xyz="0.15 0.1 0.27" rpy="0 0 0"/>
    <axis xyz="1 0 0"/>
    <limit lower="-0.524" upper="0.524" effort="15" velocity="3"/>
  </joint>

  
  <link name="leg_front_left_2">
    <visual>
      <geometry>
        <cylinder length="0.13" radius="0.01"/>
      </geometry>
      <origin xyz="0 0 -0.065" rpy="0 0 0" />
    </visual>
    <visual>
      <geometry>
        <sphere radius="0.02" />
      </geometry>
      <origin xyz="0 0 0" rpy="0 0 0" />
    </visual>
  </link>

  <joint name="joint_front_left_2" type="revolute">
    <parent link="leg_front_left_1"/>
    <child link="leg_front_left_2"/>
    <origin xyz="0 0.04 0" rpy="0 0 0"/>
    <axis xyz="0 1 0"/>
    <limit lower="0" upper="1.571" effort="15" velocity="3"/>
  </joint>


  <link name="leg_front_left_3">
    <visual>
      <geometry>
        <cylinder length="0.12" radius="0.01"/>
      </geometry>
      <origin xyz="0 0 -0.06" rpy="0 0 0" />
    </visual>
    <visual>
      <geometry>
        <sphere radius="0.02" />
      </geometry>
      <origin xyz="0 0 0" rpy="0 0 0" />
    </visual>
    <visual>
      <geometry>
        <sphere radius="0.02" />
      </geometry>
      <origin xyz="0 0 -0.12" rpy="0 0 0" />
    </visual>
  </link>

  <joint name="joint_front_left_3" type="revolute">
    <parent link="leg_front_left_2"/>
    <child link="leg_front_left_3"/>
    <origin xyz="0 0 -0.13" rpy="0 0 0"/>
    <axis xyz="0 1 0"/>
    <limit lower="-2.094" upper="0" effort="15" velocity="3"/>
  </joint>


  <!-- front_right -->
  <link name="leg_front_right_1">
    <visual>
      <geometry>
        <cylinder length="0.04" radius="0.01"/>
      </geometry>
      <origin xyz="0 -0.02 0" rpy="1.5705 0 0" />
    </visual>
    <visual>
      <geometry>
        <sphere radius="0.02" />
      </geometry>
      <origin xyz="0 0 0" rpy="0 0 0" />
    </visual>
  </link>

  <joint name="joint_front_right_1" type="revolute">
    <parent link="base_link"/>
    <child link="leg_front_right_1"/>
    <origin xyz="0.15 -0.1 0.27" rpy="0 0 0"/>
    <axis xyz="1 0 0"/>
    <limit lower="-0.524" upper="0.524" effort="15" velocity="3"/>
  </joint>

  
  <link name="leg_front_right_2">
    <visual>
      <geometry>
        <cylinder length="0.13" radius="0.01"/>
      </geometry>
      <origin xyz="0 0 -0.065" rpy="0 0 0" />
    </visual>
    <visual>
      <geometry>
        <sphere radius="0.02" />
      </geometry>
      <origin xyz="0 0 0" rpy="0 0 0" />
    </visual>
  </link>

  <joint name="joint_front_right_2" type="revolute">
    <parent link="leg_front_right_1"/>
    <child link="leg_front_right_2"/>
    <origin xyz="0 -0.04 0" rpy="0 0 0"/>
    <axis xyz="0 1 0"/>
    <limit lower="0" upper="1.571" effort="15" velocity="3"/>
  </joint>


  <link name="leg_front_right_3">
    <visual>
      <geometry>
        <cylinder length="0.12" radius="0.01"/>
      </geometry>
      <origin xyz="0 0 -0.06" rpy="0 0 0" />
    </visual>
    <visual>
      <geometry>
        <sphere radius="0.02" />
      </geometry>
      <origin xyz="0 0 0" rpy="0 0 0" />
    </visual>
    <visual>
      <geometry>
        <sphere radius="0.02" />
      </geometry>
      <origin xyz="0 0 -0.12" rpy="0 0 0" />
    </visual>
  </link>

  <joint name="joint_front_right_3" type="revolute">
    <parent link="leg_front_right_2"/>
    <child link="leg_front_right_3"/>
    <origin xyz="0 0 -0.13" rpy="0 0 0"/>
    <axis xyz="0 1 0"/>
    <limit lower="-2.094" upper="0" effort="15" velocity="3"/>
  </joint>


  <!-- rear_left -->
  <link name="leg_rear_left_1">
    <visual>
      <geometry>
        <cylinder length="0.04" radius="0.01"/>
      </geometry>
      <origin xyz="0 0.02 0" rpy="1.5705 0 0" />
    </visual>
    <visual>
      <geometry>
        <sphere radius="0.02" />
      </geometry>
      <origin xyz="0 0 0" rpy="0 0 0" />
    </visual>
  </link>

  <joint name="joint_rear_left_1" type="revolute">
    <parent link="base_link"/>
    <child link="leg_rear_left_1"/>
    <origin xyz="-0.15 0.1 0.27" rpy="0 0 0"/>
    <axis xyz="1 0 0"/>
    <limit lower="-0.524" upper="0.524" effort="15" velocity="3"/>
  </joint>

  
  <link name="leg_rear_left_2">
    <visual>
      <geometry>
        <cylinder length="0.13" radius="0.01"/>
      </geometry>
      <origin xyz="0 0 -0.065" rpy="0 0 0" />
    </visual>
    <visual>
      <geometry>
        <sphere radius="0.02" />
      </geometry>
      <origin xyz="0 0 0" rpy="0 0 0" />
    </visual>
  </link>

  <joint name="joint_rear_left_2" type="revolute">
    <parent link="leg_rear_left_1"/>
    <child link="leg_rear_left_2"/>
    <origin xyz="0 0.04 0" rpy="0 0 0"/>
    <axis xyz="0 1 0"/>
    <limit lower="0" upper="1.571" effort="15" velocity="3"/>
  </joint>


  <link name="leg_rear_left_3">
    <visual>
      <geometry>
        <cylinder length="0.12" radius="0.01"/>
      </geometry>
      <origin xyz="0 0 -0.06" rpy="0 0 0" />
    </visual>
    <visual>
      <geometry>
        <sphere radius="0.02" />
      </geometry>
      <origin xyz="0 0 0" rpy="0 0 0" />
    </visual>
    <visual>
      <geometry>
        <sphere radius="0.02" />
      </geometry>
      <origin xyz="0 0 -0.12" rpy="0 0 0" />
    </visual>
  </link>

  <joint name="joint_rear_left_3" type="revolute">
    <parent link="leg_rear_left_2"/>
    <child link="leg_rear_left_3"/>
    <origin xyz="0 0 -0.13" rpy="0 0 0"/>
    <axis xyz="0 1 0"/>
    <limit lower="-2.094" upper="0" effort="15" velocity="3"/>
  </joint>


  <!-- rear_right -->
  <link name="leg_rear_right_1">
    <visual>
      <geometry>
        <cylinder length="0.04" radius="0.01"/>
      </geometry>
      <origin xyz="0 -0.02 0" rpy="1.5705 0 0" />
    </visual>
    <visual>
      <geometry>
        <sphere radius="0.02" />
      </geometry>
      <origin xyz="0 0 0" rpy="0 0 0" />
    </visual>
  </link>

  <joint name="joint_rear_right_1" type="revolute">
    <parent link="base_link"/>
    <child link="leg_rear_right_1"/>
    <origin xyz="-0.15 -0.1 0.27" rpy="0 0 0"/>
    <axis xyz="1 0 0"/>
    <limit lower="-0.524" upper="0.524" effort="15" velocity="3"/>
  </joint>

  
  <link name="leg_rear_right_2">
    <visual>
      <geometry>
        <cylinder length="0.13" radius="0.01"/>
      </geometry>
      <origin xyz="0 0 -0.065" rpy="0 0 0" />
    </visual>
    <visual>
      <geometry>
        <sphere radius="0.02" />
      </geometry>
      <origin xyz="0 0 0" rpy="0 0 0" />
    </visual>
  </link>

  <joint name="joint_rear_right_2" type="revolute">
    <parent link="leg_rear_right_1"/>
    <child link="leg_rear_right_2"/>
    <origin xyz="0 -0.04 0" rpy="0 0 0"/>
    <axis xyz="0 1 0"/>
    <limit lower="0" upper="1.571" effort="15" velocity="3"/>
  </joint>


  <link name="leg_rear_right_3">
    <visual>
      <geometry>
        <cylinder length="0.12" radius="0.01"/>
      </geometry>
      <origin xyz="0 0 -0.06" rpy="0 0 0" />
    </visual>
    <visual>
      <geometry>
        <sphere radius="0.02" />
      </geometry>
      <origin xyz="0 0 0" rpy="0 0 0" />
    </visual>
    <visual>
      <geometry>
        <sphere radius="0.02" />
      </geometry>
      <origin xyz="0 0 -0.12" rpy="0 0 0" />
    </visual>
  </link>

  <joint name="joint_rear_right_3" type="revolute">
    <parent link="leg_rear_right_2"/>
    <child link="leg_rear_right_3"/>
    <origin xyz="0 0 -0.13" rpy="0 0 0"/>
    <axis xyz="0 1 0"/>
    <limit lower="-2.094" upper="0" effort="15" velocity="3"/>
  </joint>

</robot>
